[2025-07-15T19:50:28.501+0000] {local_task_job_runner.py:120} INFO - ::group::Pre task execution logs
[2025-07-15T19:50:28.538+0000] {taskinstance.py:2076} INFO - Dependencies all met for dep_context=non-requeueable deps ti=<TaskInstance: flight_model_training.train_and_log_model manual__2025-07-15T19:50:25.923834+00:00 [queued]>
[2025-07-15T19:50:28.547+0000] {taskinstance.py:2076} INFO - Dependencies all met for dep_context=requeueable deps ti=<TaskInstance: flight_model_training.train_and_log_model manual__2025-07-15T19:50:25.923834+00:00 [queued]>
[2025-07-15T19:50:28.548+0000] {taskinstance.py:2306} INFO - Starting attempt 1 of 1
[2025-07-15T19:50:28.565+0000] {taskinstance.py:2330} INFO - Executing <Task(PythonOperator): train_and_log_model> on 2025-07-15 19:50:25.923834+00:00
[2025-07-15T19:50:28.576+0000] {standard_task_runner.py:63} INFO - Started process 299 to run task
[2025-07-15T19:50:28.593+0000] {standard_task_runner.py:90} INFO - Running: ['***', 'tasks', 'run', 'flight_model_training', 'train_and_log_model', 'manual__2025-07-15T19:50:25.923834+00:00', '--job-id', '3', '--raw', '--subdir', 'DAGS_FOLDER/flight_model_dag.py', '--cfg-path', '/tmp/tmpn1_2n8ki']
[2025-07-15T19:50:28.603+0000] {standard_task_runner.py:91} INFO - Job 3: Subtask train_and_log_model
[2025-07-15T19:50:28.701+0000] {task_command.py:426} INFO - Running <TaskInstance: flight_model_training.train_and_log_model manual__2025-07-15T19:50:25.923834+00:00 [running]> on host 778895c79c4a
[2025-07-15T19:50:28.805+0000] {taskinstance.py:2648} INFO - Exporting env vars: AIRFLOW_CTX_DAG_OWNER='***' AIRFLOW_CTX_DAG_ID='flight_model_training' AIRFLOW_CTX_TASK_ID='train_and_log_model' AIRFLOW_CTX_EXECUTION_DATE='2025-07-15T19:50:25.923834+00:00' AIRFLOW_CTX_TRY_NUMBER='1' AIRFLOW_CTX_DAG_RUN_ID='manual__2025-07-15T19:50:25.923834+00:00'
[2025-07-15T19:50:28.807+0000] {taskinstance.py:430} INFO - ::endgroup::
[2025-07-15T19:50:28.826+0000] {taskinstance.py:441} INFO - ::group::Post task execution logs
[2025-07-15T19:50:28.827+0000] {taskinstance.py:2905} ERROR - Task failed with exception
Traceback (most recent call last):
  File "/home/airflow/.local/lib/python3.11/site-packages/airflow/models/taskinstance.py", line 465, in _execute_task
    result = _execute_callable(context=context, **execute_callable_kwargs)
             ^^^^^^^^^^^^^^^^^^^^^^^^^^^^^^^^^^^^^^^^^^^^^^^^^^^^^^^^^^^^^
  File "/home/airflow/.local/lib/python3.11/site-packages/airflow/models/taskinstance.py", line 432, in _execute_callable
    return execute_callable(context=context, **execute_callable_kwargs)
           ^^^^^^^^^^^^^^^^^^^^^^^^^^^^^^^^^^^^^^^^^^^^^^^^^^^^^^^^^^^^
  File "/home/airflow/.local/lib/python3.11/site-packages/airflow/models/baseoperator.py", line 400, in wrapper
    return func(self, *args, **kwargs)
           ^^^^^^^^^^^^^^^^^^^^^^^^^^^
  File "/home/airflow/.local/lib/python3.11/site-packages/airflow/operators/python.py", line 235, in execute
    return_value = self.execute_callable()
                   ^^^^^^^^^^^^^^^^^^^^^^^
  File "/home/airflow/.local/lib/python3.11/site-packages/airflow/operators/python.py", line 252, in execute_callable
    return self.python_callable(*self.op_args, **self.op_kwargs)
           ^^^^^^^^^^^^^^^^^^^^^^^^^^^^^^^^^^^^^^^^^^^^^^^^^^^^^
  File "/opt/airflow/dags/flight_model_dag.py", line 16, in train_model
    df = pd.read_csv('/opt/airflow/data/flights.csv')
         ^^^^^^^^^^^^^^^^^^^^^^^^^^^^^^^^^^^^^^^^^^^^
  File "/home/airflow/.local/lib/python3.11/site-packages/pandas/io/parsers/readers.py", line 948, in read_csv
    return _read(filepath_or_buffer, kwds)
           ^^^^^^^^^^^^^^^^^^^^^^^^^^^^^^^
  File "/home/airflow/.local/lib/python3.11/site-packages/pandas/io/parsers/readers.py", line 611, in _read
    parser = TextFileReader(filepath_or_buffer, **kwds)
             ^^^^^^^^^^^^^^^^^^^^^^^^^^^^^^^^^^^^^^^^^^
  File "/home/airflow/.local/lib/python3.11/site-packages/pandas/io/parsers/readers.py", line 1448, in __init__
    self._engine = self._make_engine(f, self.engine)
                   ^^^^^^^^^^^^^^^^^^^^^^^^^^^^^^^^^
  File "/home/airflow/.local/lib/python3.11/site-packages/pandas/io/parsers/readers.py", line 1705, in _make_engine
    self.handles = get_handle(
                   ^^^^^^^^^^^
  File "/home/airflow/.local/lib/python3.11/site-packages/pandas/io/common.py", line 863, in get_handle
    handle = open(
             ^^^^^
FileNotFoundError: [Errno 2] No such file or directory: '/opt/airflow/data/flights.csv'
[2025-07-15T19:50:28.868+0000] {taskinstance.py:1206} INFO - Marking task as FAILED. dag_id=flight_model_training, task_id=train_and_log_model, run_id=manual__2025-07-15T19:50:25.923834+00:00, execution_date=20250715T195025, start_date=20250715T195028, end_date=20250715T195028
[2025-07-15T19:50:28.888+0000] {standard_task_runner.py:110} ERROR - Failed to execute job 3 for task train_and_log_model ([Errno 2] No such file or directory: '/opt/airflow/data/flights.csv'; 299)
[2025-07-15T19:50:28.924+0000] {local_task_job_runner.py:240} INFO - Task exited with return code 1
[2025-07-15T19:50:28.941+0000] {taskinstance.py:3498} INFO - 0 downstream tasks scheduled from follow-on schedule check
[2025-07-15T19:50:28.944+0000] {local_task_job_runner.py:222} INFO - ::endgroup::
