[2025-07-15T19:57:20.053+0000] {local_task_job_runner.py:120} INFO - ::group::Pre task execution logs
[2025-07-15T19:57:20.078+0000] {taskinstance.py:2076} INFO - Dependencies all met for dep_context=non-requeueable deps ti=<TaskInstance: flight_model_training.train_and_log_model manual__2025-07-15T19:57:17.624021+00:00 [queued]>
[2025-07-15T19:57:20.085+0000] {taskinstance.py:2076} INFO - Dependencies all met for dep_context=requeueable deps ti=<TaskInstance: flight_model_training.train_and_log_model manual__2025-07-15T19:57:17.624021+00:00 [queued]>
[2025-07-15T19:57:20.086+0000] {taskinstance.py:2306} INFO - Starting attempt 1 of 1
[2025-07-15T19:57:20.095+0000] {taskinstance.py:2330} INFO - Executing <Task(PythonOperator): train_and_log_model> on 2025-07-15 19:57:17.624021+00:00
[2025-07-15T19:57:20.107+0000] {standard_task_runner.py:63} INFO - Started process 300 to run task
[2025-07-15T19:57:20.119+0000] {standard_task_runner.py:90} INFO - Running: ['***', 'tasks', 'run', 'flight_model_training', 'train_and_log_model', 'manual__2025-07-15T19:57:17.624021+00:00', '--job-id', '2', '--raw', '--subdir', 'DAGS_FOLDER/flight_model_dag.py', '--cfg-path', '/tmp/tmp7vi885z3']
[2025-07-15T19:57:20.123+0000] {standard_task_runner.py:91} INFO - Job 2: Subtask train_and_log_model
[2025-07-15T19:57:20.171+0000] {task_command.py:426} INFO - Running <TaskInstance: flight_model_training.train_and_log_model manual__2025-07-15T19:57:17.624021+00:00 [running]> on host 65b630699360
[2025-07-15T19:57:20.275+0000] {taskinstance.py:2648} INFO - Exporting env vars: AIRFLOW_CTX_DAG_OWNER='***' AIRFLOW_CTX_DAG_ID='flight_model_training' AIRFLOW_CTX_TASK_ID='train_and_log_model' AIRFLOW_CTX_EXECUTION_DATE='2025-07-15T19:57:17.624021+00:00' AIRFLOW_CTX_TRY_NUMBER='1' AIRFLOW_CTX_DAG_RUN_ID='manual__2025-07-15T19:57:17.624021+00:00'
[2025-07-15T19:57:20.276+0000] {taskinstance.py:430} INFO - ::endgroup::
[2025-07-15T19:58:09.425+0000] {taskinstance.py:441} INFO - ::group::Post task execution logs
[2025-07-15T19:58:09.426+0000] {taskinstance.py:2905} ERROR - Task failed with exception
Traceback (most recent call last):
  File "/home/airflow/.local/lib/python3.11/site-packages/airflow/models/taskinstance.py", line 465, in _execute_task
    result = _execute_callable(context=context, **execute_callable_kwargs)
             ^^^^^^^^^^^^^^^^^^^^^^^^^^^^^^^^^^^^^^^^^^^^^^^^^^^^^^^^^^^^^
  File "/home/airflow/.local/lib/python3.11/site-packages/airflow/models/taskinstance.py", line 432, in _execute_callable
    return execute_callable(context=context, **execute_callable_kwargs)
           ^^^^^^^^^^^^^^^^^^^^^^^^^^^^^^^^^^^^^^^^^^^^^^^^^^^^^^^^^^^^
  File "/home/airflow/.local/lib/python3.11/site-packages/airflow/models/baseoperator.py", line 400, in wrapper
    return func(self, *args, **kwargs)
           ^^^^^^^^^^^^^^^^^^^^^^^^^^^
  File "/home/airflow/.local/lib/python3.11/site-packages/airflow/operators/python.py", line 235, in execute
    return_value = self.execute_callable()
                   ^^^^^^^^^^^^^^^^^^^^^^^
  File "/home/airflow/.local/lib/python3.11/site-packages/airflow/operators/python.py", line 252, in execute_callable
    return self.python_callable(*self.op_args, **self.op_kwargs)
           ^^^^^^^^^^^^^^^^^^^^^^^^^^^^^^^^^^^^^^^^^^^^^^^^^^^^^
  File "/opt/airflow/dags/flight_model_dag.py", line 45, in train_model
    mlflow.set_experiment("flight_price_airflow")
  File "/home/airflow/.local/lib/python3.11/site-packages/mlflow/tracking/fluent.py", line 183, in set_experiment
    experiment = client.get_experiment_by_name(experiment_name)
                 ^^^^^^^^^^^^^^^^^^^^^^^^^^^^^^^^^^^^^^^^^^^^^^
  File "/home/airflow/.local/lib/python3.11/site-packages/mlflow/tracking/_tracking_service/client.py", line 258, in get_experiment_by_name
    return self.store.get_experiment_by_name(name)
           ^^^^^^^^^^^^^^^^^^^^^^^^^^^^^^^^^^^^^^^
  File "/home/airflow/.local/lib/python3.11/site-packages/mlflow/store/tracking/rest_store.py", line 869, in get_experiment_by_name
    response_proto = self._call_endpoint(GetExperimentByName, req_body)
                     ^^^^^^^^^^^^^^^^^^^^^^^^^^^^^^^^^^^^^^^^^^^^^^^^^^
  File "/home/airflow/.local/lib/python3.11/site-packages/mlflow/store/tracking/rest_store.py", line 135, in _call_endpoint
    return call_endpoint(
           ^^^^^^^^^^^^^^
  File "/home/airflow/.local/lib/python3.11/site-packages/mlflow/utils/rest_utils.py", line 590, in call_endpoint
    response = verify_rest_response(response, endpoint)
               ^^^^^^^^^^^^^^^^^^^^^^^^^^^^^^^^^^^^^^^^
  File "/home/airflow/.local/lib/python3.11/site-packages/mlflow/utils/rest_utils.py", line 310, in verify_rest_response
    raise MlflowException(
mlflow.exceptions.MlflowException: API request to endpoint /api/2.0/mlflow/experiments/get-by-name failed with error code 404 != 200. Response body: '<!doctype html>
<html lang=en>
<title>404 Not Found</title>
<h1>Not Found</h1>
<p>The requested URL was not found on the server. If you entered the URL manually please check your spelling and try again.</p>
'
[2025-07-15T19:58:09.446+0000] {taskinstance.py:1206} INFO - Marking task as FAILED. dag_id=flight_model_training, task_id=train_and_log_model, run_id=manual__2025-07-15T19:57:17.624021+00:00, execution_date=20250715T195717, start_date=20250715T195720, end_date=20250715T195809
[2025-07-15T19:58:09.459+0000] {standard_task_runner.py:110} ERROR - Failed to execute job 2 for task train_and_log_model (API request to endpoint /api/2.0/mlflow/experiments/get-by-name failed with error code 404 != 200. Response body: '<!doctype html>
<html lang=en>
<title>404 Not Found</title>
<h1>Not Found</h1>
<p>The requested URL was not found on the server. If you entered the URL manually please check your spelling and try again.</p>
'; 300)
[2025-07-15T19:58:09.487+0000] {local_task_job_runner.py:240} INFO - Task exited with return code 1
[2025-07-15T19:58:09.501+0000] {taskinstance.py:3498} INFO - 0 downstream tasks scheduled from follow-on schedule check
[2025-07-15T19:58:09.503+0000] {local_task_job_runner.py:222} INFO - ::endgroup::
