[2025-07-15T20:25:07.263+0000] {local_task_job_runner.py:120} INFO - ::group::Pre task execution logs
[2025-07-15T20:25:07.292+0000] {taskinstance.py:2076} INFO - Dependencies all met for dep_context=non-requeueable deps ti=<TaskInstance: flight_model_training.train_and_log_model manual__2025-07-15T20:25:04.665593+00:00 [queued]>
[2025-07-15T20:25:07.300+0000] {taskinstance.py:2076} INFO - Dependencies all met for dep_context=requeueable deps ti=<TaskInstance: flight_model_training.train_and_log_model manual__2025-07-15T20:25:04.665593+00:00 [queued]>
[2025-07-15T20:25:07.302+0000] {taskinstance.py:2306} INFO - Starting attempt 1 of 1
[2025-07-15T20:25:07.315+0000] {taskinstance.py:2330} INFO - Executing <Task(PythonOperator): train_and_log_model> on 2025-07-15 20:25:04.665593+00:00
[2025-07-15T20:25:07.322+0000] {standard_task_runner.py:63} INFO - Started process 300 to run task
[2025-07-15T20:25:07.333+0000] {standard_task_runner.py:90} INFO - Running: ['***', 'tasks', 'run', 'flight_model_training', 'train_and_log_model', 'manual__2025-07-15T20:25:04.665593+00:00', '--job-id', '2', '--raw', '--subdir', 'DAGS_FOLDER/flight_model_dag.py', '--cfg-path', '/tmp/tmprw04ztrc']
[2025-07-15T20:25:07.339+0000] {standard_task_runner.py:91} INFO - Job 2: Subtask train_and_log_model
[2025-07-15T20:25:07.404+0000] {task_command.py:426} INFO - Running <TaskInstance: flight_model_training.train_and_log_model manual__2025-07-15T20:25:04.665593+00:00 [running]> on host 9bf486a052b0
[2025-07-15T20:25:07.486+0000] {taskinstance.py:2648} INFO - Exporting env vars: AIRFLOW_CTX_DAG_OWNER='***' AIRFLOW_CTX_DAG_ID='flight_model_training' AIRFLOW_CTX_TASK_ID='train_and_log_model' AIRFLOW_CTX_EXECUTION_DATE='2025-07-15T20:25:04.665593+00:00' AIRFLOW_CTX_TRY_NUMBER='1' AIRFLOW_CTX_DAG_RUN_ID='manual__2025-07-15T20:25:04.665593+00:00'
[2025-07-15T20:25:07.488+0000] {taskinstance.py:430} INFO - ::endgroup::
[2025-07-15T20:25:53.335+0000] {logging_mixin.py:188} WARNING - 2025/07/15 20:25:53 WARNING mlflow.utils.git_utils: Failed to import Git (the Git executable is probably not on your PATH), so Git SHA is not available. Error: Failed to initialize: Bad git executable.
The git executable must be specified in one of the following ways:
    - be included in your $PATH
    - be set via $GIT_PYTHON_GIT_EXECUTABLE
    - explicitly set via git.refresh(<full-path-to-git-executable>)

All git commands will error until this is rectified.

This initial message can be silenced or aggravated in the future by setting the
$GIT_PYTHON_REFRESH environment variable. Use one of the following values:
    - quiet|q|silence|s|silent|none|n|0: for no message or exception
    - warn|w|warning|log|l|1: for a warning message (logging level CRITICAL, displayed by default)
    - error|e|exception|raise|r|2: for a raised exception

Example:
    export GIT_PYTHON_REFRESH=quiet
[2025-07-15T20:25:54.134+0000] {logging_mixin.py:188} INFO - üèÉ View run enthused-donkey-598 at: http://mlflow:5000/#/experiments/474368820096796256/runs/34b78dc468f740ea89dca33b6294c071
[2025-07-15T20:25:54.135+0000] {logging_mixin.py:188} INFO - üß™ View experiment at: http://mlflow:5000/#/experiments/474368820096796256
[2025-07-15T20:25:54.195+0000] {taskinstance.py:441} INFO - ::group::Post task execution logs
[2025-07-15T20:25:54.196+0000] {taskinstance.py:2905} ERROR - Task failed with exception
Traceback (most recent call last):
  File "/home/airflow/.local/lib/python3.11/site-packages/airflow/models/taskinstance.py", line 465, in _execute_task
    result = _execute_callable(context=context, **execute_callable_kwargs)
             ^^^^^^^^^^^^^^^^^^^^^^^^^^^^^^^^^^^^^^^^^^^^^^^^^^^^^^^^^^^^^
  File "/home/airflow/.local/lib/python3.11/site-packages/airflow/models/taskinstance.py", line 432, in _execute_callable
    return execute_callable(context=context, **execute_callable_kwargs)
           ^^^^^^^^^^^^^^^^^^^^^^^^^^^^^^^^^^^^^^^^^^^^^^^^^^^^^^^^^^^^
  File "/home/airflow/.local/lib/python3.11/site-packages/airflow/models/baseoperator.py", line 400, in wrapper
    return func(self, *args, **kwargs)
           ^^^^^^^^^^^^^^^^^^^^^^^^^^^
  File "/home/airflow/.local/lib/python3.11/site-packages/airflow/operators/python.py", line 235, in execute
    return_value = self.execute_callable()
                   ^^^^^^^^^^^^^^^^^^^^^^^
  File "/home/airflow/.local/lib/python3.11/site-packages/airflow/operators/python.py", line 252, in execute_callable
    return self.python_callable(*self.op_args, **self.op_kwargs)
           ^^^^^^^^^^^^^^^^^^^^^^^^^^^^^^^^^^^^^^^^^^^^^^^^^^^^^
  File "/opt/airflow/dags/flight_model_dag.py", line 50, in train_model
    mlflow.log_metric("rmse", rmse = np.sqrt(mean_squared_error(y_test, y_pred)))
TypeError: log_metric() got an unexpected keyword argument 'rmse'
[2025-07-15T20:25:54.212+0000] {taskinstance.py:1206} INFO - Marking task as FAILED. dag_id=flight_model_training, task_id=train_and_log_model, run_id=manual__2025-07-15T20:25:04.665593+00:00, execution_date=20250715T202504, start_date=20250715T202507, end_date=20250715T202554
[2025-07-15T20:25:54.227+0000] {standard_task_runner.py:110} ERROR - Failed to execute job 2 for task train_and_log_model (log_metric() got an unexpected keyword argument 'rmse'; 300)
[2025-07-15T20:25:54.282+0000] {local_task_job_runner.py:240} INFO - Task exited with return code 1
[2025-07-15T20:25:54.295+0000] {taskinstance.py:3498} INFO - 0 downstream tasks scheduled from follow-on schedule check
[2025-07-15T20:25:54.297+0000] {local_task_job_runner.py:222} INFO - ::endgroup::
